Workbook

Sheet 00 COMMAND CENTER
B4: ◆ LIQUIDITY
D5: TOTAL LIQUID | J5: CANCEL SAV/YR
D6: =CALC!E162 -> R$ 23196,9000 | J6: =CALC!E175 -> R$ 4389,6000
B12: ◆ LIFESTYLE & SUBSCRIPTION STACK
B13: CARD SPEND H1 | D13: CARD AVG/MO | H13: SUB STACK/MO | J13: CANCEL SAV/MO
B14: =CALC!E170 -> R$ 37245,76000
B16: ◆ MoM SIGNALS (Jun vs May 2026) — ▲=good ▼=bad (inverted for costs)
B17: Card Spend | F17: PIX Out | J17: Sub Stack
B18: =CALC!C488 -> ▲ | C18: =CALC!D488 -> -66.3% | F18: =CALC!C490 -> ▲ | G18: =CALC!D490 -> -98.0% | J18: =CALC!C493 -> ▲ | K18: =CALC!D493 -> +0.0%
B20: ◆ PRIORITY ACTIONS — live from 08 ALERTS
B21: # | C21: SEV | D21: DOMAIN | E21: FINDING | I21: EXPOSURE | J21: STATUS
B22: # | C22: Severity | D22: Domain | E22: Finding | I22: BRL Exposure | J22: Status
B23: 1 | C23: CRITICAL | D23: Subscriptions | E23: 4 services flagged CANCEL: Claude x2 (0/mo), Grok (R$14… | I23: — | J23: ⏳ Pending
B24: 2 | C24: CRITICAL | D24: Subscription Stack Bloat | E24: R$0/mo in REVIEW = 3 services undecided. Annual exposur… | I24: — | J24: ⏳ Pending
B25: 3 | C25: HIGH | D25: Liquidity Concentration | E25: 100% of liquid assets in 2 digital banks (Inter + MP = … | I25: 23196.9 | J25: ⏳ Pending
B26: 4 | C26: HIGH | D26: Lottery/Gambling Spend | E26: R$6,455 in Loteria charges on MP card 2026. No budget c… | I26: 6455.1 | J26: ⏳ Pending
B27: 5 | C27: MEDIUM | D27: AI/Tech Card Overlap | E27: R$6,624 charged via card on IA/Tech. Likely duplicates … | I27: 6624.36 | J27: ⏳ Pending
B28: 6 | C28: MEDIUM | D28: Travel/Viagem Spend | E28: R$9,037 in travel charges. Review vs business vs person… | I28: 9036.83 | J28: ⏳ Pending
B29: 7 | C29: MEDIUM | D29: ML Compras Volume | E29: R$31,570 in Mercado Livre purchases (69 items). Strong … | I29: 31570.45 | J29: ⏳ Pending
B31: KPI tiles live → CALC: Total Liquid · Cancel Sav/Yr · Card Spend H1 · MoM arrows: 3 · Alerts: 08 ALERTS · Scope: domestic outflows only (updated 2026-09-10)

Sheet CALC
B1: CALC — Single Source of Truth · financas-2026 · Eduardo Forster Giovannini
B2: Built 2026-07-14 · All values sourced from financas2026-DataEntry.xlsx · Scope cut 2026-09-10: domestic outflows only (foreign, inflows, net worth removed; cleared in place)
B4: SECTION 1 · BANK BALANCES — Confirmed 13/Jul/2026
B5: Institution | C5: Balance (BRL) | D5: Prev Balance | E5: Type | F5: Confirmed | G5: Status
B6: Banco Inter | C6: 18934.67 | D6: 42112.59 | E6: Digital | F6: 13/Jul/2026 | G6: CONFIRMED
B7: Mercado Pago | C7: 4262.23 | D7: 10102.81 | E7: Digital | F7: 12/Jul/2026 | G7: CONFIRMED
B8: BB Brasil | C8: 0 | D8: 0 | E8: Checking | F8: 13/Jul/2026 | G8: CONFIRMED
B9: BCB Registrato | C9: 0 | D9: 0 | E9: Registry | F9: 29/Jun/2026 | G9: REGISTRY
B10: TOTAL LIQUID | C10: =SUM(C6:C9) -> 23196.9
B12: SECTION 2 · FX OPERATIONS — REMOVED 2026-09-10 (out of scope: foreign / inflows)
B63: SECTION 3 · MP FATURAS MONTHLY SUMMARY — 146 Transactions
B64: Month | C64: Card Spend (R$) | D64: Transactions | E64: vs Avg | F64: Cum Total
B65: 2026-01 | C65: 3745.4 | D65: 18 | E65: -2462.2267 | F65: 3745.4
B66: 2026-02 | C66: 9515.9 | D66: 21 | E66: 3308.2733 | F66: 13261.3
B67: 2026-03 | C67: 14231.47 | D67: 32 | E67: 8023.8433 | F67: 27492.77
B68: 2026-04 | C68: 5330.44 | D68: 33 | E68: -877.18667 | F68: 32823.21
B69: 2026-05 | C69: 3308.38 | D69: 29 | E69: -2899.2467 | F69: 36131.59
B70: 2026-06 | C70: 1114.17 | D70: 13 | E70: -5093.4567 | F70: 37245.76
B71: TOTAL H1 2026 | C71: 37245.76 | D71: 146
B73: SECTION 3b · MoM CHANGES — Most Recent Month First
B74: Month | C74: Spend | D74: Prev Month Spend | E74: MoM % | F74: Direction
B75: 2026-06 | C75: 1114.17 | D75: 3308.38 | E75: -0.66322792 | F75: ↓
B76: 2026-05 | C76: 3308.38 | D76: 5330.44 | E76: -0.37934204 | F76: ↓
B77: 2026-04 | C77: 5330.44 | D77: 14231.47 | E77: -0.62544698 | F77: ↓
B78: 2026-03 | C78: 14231.47 | D78: 9515.9 | E78: 0.4955464 | F78: ↑
B79: 2026-02 | C79: 9515.9 | D79: 3745.4 | E79: 1.5406899 | F79: ↑
B80: 2026-01 | C80: 3745.4 | D80: 0 | E80: 0 | F80: ↑
B82: SECTION 4 · SPEND BY CATEGORY — Sorted Largest to Smallest
B83: Category | C83: Total (R$) | D83: % of Total | E83: Avg/Month | F83: Transactions | G83: Classification
B84: Viagem | C84: 9036.83 | D84: 0.24262708 | E84: 1506.1383 | F84: 1 | G84: 💡 Discretionary
B85: Compras/ML | C85: 8744.68 | D85: 0.23478323 | E85: 1457.4467 | F85: 9 | G85: 💡 Discretionary
B86: IA/Tecnologia | C86: 6624.36 | D86: 0.17785541 | E86: 1104.06 | F86: 37 | G86: ⚠ Review
B87: Loteria | C87: 6455.1 | D87: 0.173311 | E87: 1075.85 | F87: 39 | G87: ⚠ Review
B88: Outros | C88: 2235.58 | D88: 0.060022403 | E88: 372.59667 | F88: 9 | G88: ❓ Unknown
B89: Internet | C89: 1413.12 | D89: 0.037940426 | E89: 235.52 | F89: 6 | G89: ✅ Essential
B90: Assinatura | C90: 1227.5 | D90: 0.032956771 | E90: 204.58333 | F90: 19 | G90: 💡 Discretionary
B91: Delivery/iFood | C91: 1217.92 | D91: 0.032699561 | E91: 202.98667 | F91: 14 | G91: ✅ Essential
B92: Transporte | C92: 205.34 | D92: 0.0055131108 | E92: 34.223333 | F92: 10 | G92: 💡 Discretionary
B93: Telecomunicações | C93: 74.43 | D93: 0.0019983483 | E93: 12.405 | F93: 1 | G93: ✅ Essential
B94: Digital | C94: 10.9 | D94: 0.00029265076 | E94: 1.8166667 | F94: 1 | G94: ❓ Unknown
...

Sheet 02 CAPITAL FLOWS
B1: OUTFLOWS · Jan–Jun 2026 · Card + PIX Out (domestic)
B3: MONTHLY OUTFLOW SUMMARY
B4: Month | C4: Card Spend | D4: PIX Out | E4: Total Out
B5: 2026-01 | C5: 3745.4 | D5: 0 | E5: =C5+D5 -> 3745.4
B6: 2026-02 | C6: 9515.9 | D6: 0 | E6: =C6+D6 -> 9515.9
B7: 2026-03 | C7: 14231.47 | D7: 11432.41 | E7: =C7+D7 -> 25663.88
B8: 2026-04 | C8: 5330.44 | D8: 10330 | E8: =C8+D8 -> 15660.44
B9: 2026-05 | C9: 3308.38 | D9: 23620 | E9: =C9+D9 -> 26928.38
B10: 2026-06 | C10: 1114.17 | D10: 480 | E10: =C10+D10 -> 1594.17
B13: TRANSACTION LOG — Outflows (Card + PIX Out)
B14: Date | C14: Source | D14: Type | E14: Description | F14: BRL Amount | G14: CCY | I14: Notes
B15: 46028 | C15: MP Cartão | D15: Delivery/iFood | E15: IFD*PIZZA NOW INTERMARES | F15: -173.79 | G15: BRL | I15: Fatura 2026-02
B16: 46030 | C16: MP Cartão | D16: IA/Tecnologia | E16: Compra internacional em OPENAI *CHATGPT SUBSCR | F16: -111.58 | G16: BRL | I16: Fatura 2026-02
B17: 46030 | C17: MP Cartão | D17: Assinatura | E17: APPLE.COM/BILL | F17: -21.9 | G17: BRL | I17: Fatura 2026-02
B18: 46032 | C18: MP Cartão | D18: Delivery/iFood | E18: IFD*34531468 EDWIN LEI | F18: -111.6 | G18: BRL | I18: Fatura 2026-02
B19: 46032 | C19: MP Cartão | D19: Assinatura | E19: APPLE.COM/BILL | F19: -19.9 | G19: BRL | I19: Fatura 2026-02
B20: 46035 | C20: MP Cartão | D20: Outros | E20: MP*EDUARDOGIOVAN | F20: -0.78 | G20: BRL | I20: Fatura 2026-02
B21: 46036 | C21: MP Cartão | D21: IA/Tecnologia | E21: Compra internacional em MANUS AI | F21: -25.79 | G21: BRL | I21: Fatura 2026-02
B22: 46037 | C22: MP Cartão | D22: Internet | E22: DL*Starlink Braz | F22: -235.52 | G22: BRL | I22: Fatura 2026-02
B23: 46038 | C23: MP Cartão | D23: Loteria | E23: MP*LOTERIASONLINEU1AQ | F23: -143.6 | G23: BRL | I23: Fatura 2026-02
B24: 46038 | C24: MP Cartão | D24: Delivery/iFood | E24: IFD*FORMAGGIO RESTAURANTE | F24: -191.8 | G24: BRL | I24: Fatura 2026-02
B25: 46039 | C25: MP Cartão | D25: IA/Tecnologia | E25: Compra internacional em OPENAI *CHATGPT SUBSCR | F25: -111.37 | G25: BRL | I25: Fatura 2026-02
B26: 46039 | C26: MP Cartão | D26: Loteria | E26: MP*LOTERIASONLINE542V | F26: -111 | G26: BRL | I26: Fatura 2026-02
... B71: 46096 | C71: MP Cartão | D71: Compras/ML | E71: MERCADOLIVRE*3PRODUTOS | F71: -510.37 | G71: BRL | I71: Fatura 2026-04
B72: 46096 | C72: Banco Inter | D72: PIX Out | E72: Eduardo Forster Giovannini | F72: -6000 | G72: BRL
B73: 46096 | C73: Banco Inter | D73: PIX Out | E73: Mercado Pago Instituicao De Pagamento Ltda | F73: -4582.41 | G73: BRL
B74: 46097 | C74: MP Cartão | D74: Outros | E74: Compra internacional em ALLIANZ EVENT INS | F74: -478.17 | G74: BRL | I74: Fatura 2026-04
B75: 46098 | C75: MP Cartão | D75: IA/Tecnologia | E75: Compra internacional em OPENAI *CHATGPT SUBSCR | F75: -108.89 | G75: BRL | I75: Fatura 2026-04
B76: 46098 | C76: Banco Inter | D76: PIX Out | E76: Iago Kevyn Santos Moura | F76: -500 | G76: BRL
B77: 46099 | C77: MP Cartão | D77: Loteria | E77: MP*LOTERIASONLINENI9I | F77: -267 | G77: BRL | I77: Fatura 2026-04
B78: 46100 | C78: MP Cartão | D78: Outros | E78: Compra internacional em INTERNET ARCHIVE | F78: -53.93 | G78: BRL | I78: Fatura 2026-04
B79: 46100 | C79: MP Cartão | D79: Loteria | E79: MP*LOTERIASONLINEU38A | F79: -119 | G79: BRL | I79: Fatura 2026-04
B80: 46101 | C80: MP Cartão | D80: Assinatura | E80: EC*GOOGLEBRASILPAGAMEN | F80: -96.99 | G80: BRL | I80: Fatura 2026-04
B81: 46101 | C81: Banco Inter | D81: PIX Out | E81: Eduardo Silva Dos Santos | F81: -350 | G81: BRL
B82: 46102 | C82: MP Cartão | D82: Compras/ML | E82: MERCADOLIVRE*5PRODUTOS | F82: -119.73 | G82: BRL | I82: Fatura 2026-04
B83: 46102 | C83: MP Cartão | D83: IA/Tecnologia | E83: Compra internacional em MANUS AI | F83: -546.48 | G83: BRL | I83: Fatura 2026-04
B84: 46104 | C84: MP Cartão | D84: Loteria | E84: MP*LOTERIASONLINE12Q6 | F84: -107.5 | G84: BRL | I84: Fatura 2026-04
B85: 46107 | C85: MP Cartão | D85: Loteria | E85: MP*LOTERIASONLINEWM4R | F85: -161 | G85: BRL | I85: Fatura 2026-04
B86: 46109 | C86: MP Cartão | D86: Loteria | E86: MP*LOTERIASONLINEKBE8 | F86: -168 | G86: BRL | I86: Fatura 2026-04
B87: 46109 | C87: MP Cartão | D87: Loteria | E87: MP*LOTERIASONLINEKJOW | F87: -104 | G87: BRL | I87: Fatura 2026-04
...

Sheet 05 LIFESTYLE
B1: LIFESTYLE & BURN RATE · Card + ML + iFood · Jan–Jun 2026
B3: CARD SPEND | D3: AVG/MONTH | F3: ML+iFOOD
B4: 37245.76 | D4: 6207.6267 | F4: 27488.73
B7: CARD SPEND BY CATEGORY
B8: Category | C8: Total (R$) | D8: % of Card | E8: Avg/Month | F8: Txs | G8: Classification
B9: Viagem | C9: 9036.83 | D9: 0.24262708 | E9: 1506.1383 | F9: 1 | G9: 💡 Discretionary
B10: Compras/ML | C10: 8744.68 | D10: 0.23478323 | E10: 1457.4467 | F10: 9 | G10: 💡 Discretionary
B11: IA/Tecnologia | C11: 6624.36 | D11: 0.17785541 | E11: 1104.06 | F11: 37 | G11: ⚠ Review
B12: Loteria | C12: 6455.1 | D12: 0.173311 | E12: 1075.85 | F12: 39 | G12: ⚠ Review
B13: Outros | C13: 2235.58 | D13: 0.060022403 | E13: 372.59667 | F13: 9 | G13: 💡 Discretionary
B14: Internet | C14: 1413.12 | D14: 0.037940426 | E14: 235.52 | F14: 6 | G14: ✅ Essential
B15: Assinatura | C15: 1227.5 | D15: 0.032956771 | E15: 204.58333 | F15: 19 | G15: 💡 Discretionary
B16: Delivery/iFood | C16: 1217.92 | D16: 0.032699561 | E16: 202.98667 | F16: 14 | G16: ✅ Essential
B17: Transporte | C17: 205.34 | D17: 0.0055131108 | E17: 34.223333 | F17: 10 | G17: 💡 Discretionary
B18: Telecomunicações | C18: 74.43 | D18: 0.0019983483 | E18: 12.405 | F18: 1 | G18: ✅ Essential
B19: Digital | C19: 10.9 | D19: 0.00029265076 | E19: 1.8166667 | F19: 1 | G19: 💡 Discretionary
B22: MONTHLY CARD SPEND
B23: Month | C23: Card Spend | D23: Txs | E23: vs Avg | F23: vs Prior | G23: Notes
B24: 2026-01 | C24: 3745.4 | D24: 18 | E24: -2462.2267 | F24: 0
B25: 2026-02 | C25: 9515.9 | D25: 21 | E25: 3308.2733 | F25: 5770.5
B26: 2026-03 | C26: 14231.47 | D26: 32 | E26: 8023.8433 | F26: 4715.57
B27: 2026-04 | C27: 5330.44 | D27: 33 | E27: -877.18667 | F27: -8901.03
B28: 2026-05 | C28: 3308.38 | D28: 29 | E28: -2899.2467 | F28: -2022.06
B29: 2026-06 | C29: 1114.17 | D29: 13 | E29: -5093.4567 | F29: -2194.21
B32: MERCADO LIVRE + iFOOD ORDERS
B33: Date | C33: Platform | D33: Item | E33: Amount | F33: Category | G33: Status
B34: 2026-06-16 | C34: Mercado Livre | D34: Suporte Monitor Articulado Portátil Dobrável | E34: 144 | F34: Home Office | G34: delivered
B35: 2026-06-08 | C35: Mercado Livre | D35: Filtro De Ar Descartável Cpap Airmini Resmed | E35: 41.65 | F35: Saúde/CPAP | G35: delivered
B36: 2026-06-03 | C36: Mercado Livre | D36: Máscara Nasal Resmed Airfit N30i Apneia | E36: 480 | F36: Saúde/CPAP | G36: delivered
B37: 2026-06-01 | C37: Mercado Livre | D37: Macaco Hidráulico Tipo Jacaré 2ton Portátil | E37: 249.99 | F37: Ferramentas | G37: delivered
B38: 2026-05-30 | C38: iFood | D38: Pipa Sushi & Temakeria – 1x Monte Seu Poke | E38: 90.29 | F38: Delivery/Sushi | G38: delivered
B39: 2026-05-18 | C39: iFood | D39: Pipa Sushi & Temakeria – 1x Monte Seu Poke | E39: 67.31 | F39: Delivery/Sushi | G39: delivered
B40: 2026-05-16 | C40: iFood | D40: Maria Baunilha Confeitaria – 1x Trio Maria Baunilha | E40: 73.03 | F40: Delivery/Confeitaria | G40: delivered
B41: 2026-05-11 | C41: Mercado Livre | D41: Câmera Inteligente Im7 3mp De Resolução | E41: 429.9 | F41: Eletrônicos | G41: delivered
B42: 2026-05-11 | C42: iFood | D42: iFood (taxa/pedido) – - | E42: 7.95 | F42: Delivery/Taxa | G42: delivered
B43: 2026-05-09 | C43: Mercado Livre | D43: Sensor Presença Humana Radar Inteligente | E43: 379.98 | F43: Eletrônicos | G43: delivered
B44: 2026-05-03 | C44: Mercado Livre | D44: Prateleira Estilo Industrial Suporte Em Madeira | E44: 132 | F44: Casa | G44: delivered
B45: 2026-05-02 | C45: iFood | D45: Bianca Tolêdo Confeitaria – 1x Cake Moça e Morango + 1x Cake Cenoura | E45: 0 | F45: Delivery/Confeitaria | G45: delivered
... B102: 2026-01-03 | C102: Mercado Livre | D102: Kit Cabo+espelho Odontológico Inox | E102: 21.85 | F102: Saúde/Higiene | G102: delivered

Sheet 06 SUBSCRIPTION MGR
B1: SUBSCRIPTION MANAGER · Stack Audit · KEEP / CANCEL / REVIEW
B3: TOTAL/MONTH | D3: KEEP/MONTH | F3: CANCEL SAVINGS | H3: CANCEL / YEAR
B4: 0 | D4: 0 | F4: 0 | H4: 0
B7: FULL SUBSCRIPTION REGISTER
B8: Source | C8: Service | D8: Plan | E8: CCY | F8: Mthly BRL | G8: Category | H8: Dup Risk | I8: Decision | J8: Annual BRL
C9: Direct AI | D9: automacao.giovannini@gmail.com | E9: Pro | F9: 0 | G9: 92 | H9: AI - General/Coding | I9: HIGH | J9: 0
C10: Direct AI | D10: cadastros.online1979@gmail.com | E10: Pro | F10: 0 | G10: 92 | H10: AI - General/Coding | I10: HIGH | J10: 0
C11: Direct AI | D11: giovannini.eduardo@gmail.com | E11: Plus | F11: 0 | G11: 106 | H11: AI - General Assistant | I11: MEDIUM | J11: 0
C12: Direct AI | D12: cadastros.online1979@gmail.com | E12: Pro | F12: 0 | G12: 96.99 | H12: AI - General/Workspace | I12: HIGH | J12: 0
C13: Direct AI | D13: cadastro.giovannini@gmail.com | E13: Unknown / credits | F13: 0 | H13: AI - Agent/Credits | I13: UNKNOWN | J13: 0
C14: Direct AI | D14: automacao.giovannini@gmail.com | E14: Unknown / credits | F14: 0 | G14: 418.43 | H14: AI - Agent/Credits | I14: UNKNOWN | J14: 0
C15: Direct AI | D15: giovannini.eduardo@gmail.com | E15: Pro | F15: 0 | G15: 106 | H15: AI - Coding Assistant | I15: MEDIUM | J15: 0
C16: Direct AI | D16: automacao.giovannini@gmail.com | E16: Unlimited | F16: 0 | G16: 45.37 | H16: AI - Desktop Automation | I16: UNKNOWN | J16: 0
C17: Apple | D17: Unknown | E17: Annual Subscription | F17: 0 | G17: 15.40833333333333 | H17: Creative/Productivity | I17: LOW | J17: 0
C18: Apple | D18: Unknown | E18: SuperGrok | F18: 0 | G18: 149.9 | H18: AI - General/Media | I18: HIGH | J18: 0
C19: Apple | D19: Unknown | E19: 200 GB storage | F19: 0 | G19: 19.9 | H19: Cloud/Storage | I19: LOW | J19: 0
C20: Apple | D20: Unknown | E20: Personal | F20: 0 | G20: 42.41666666666666 | H20: Productivity/Cloud | I20: MEDIUM | J20: 0
C21: Apple | D21: Unknown | E21: Auto-renewable Subscription | F21: 0 | G21: 28.325 | H21: Security/VPN | I21: LOW | J21: 0
C22: Apple | D22: Unknown | E22: Perplexity Pro for Mac | F22: 0 | G22: 99.9 | H22: AI - Research Assistant | I22: HIGH | J22: 0
C23: Apple | D23: Unknown | E23: TuneIn Premium | F23: 0 | G23: 31.9 | H23: Entertainment | I23: LOW | J23: 0
C24: KEEP TOTAL/MONTH | E24: BRL | F24: 0 | I24: REVIEW | J24: 0
C25: CANCEL SAVINGS/MONTH | E25: BRL | F25: 0 | I25: REVIEW | J25: 0
C26: REVIEW TOTAL/MONTH | E26: BRL | F26: 0 | I26: REVIEW | J26: 0
B29: DECISION SUMMARY
B30: KEEP/month | D30: CANCEL/month | F30: REVIEW/month | H30: TOTAL/month
B31: 0 | D31: 0 | F31: 0 | H31: 0

Sheet 07 CASH BRIDGE
B1: CASH BRIDGE · Banco Inter Account 6627102 · PIX Out (domestic)
D3: PIX OUT
D4: 45862.41
F7: FINAL BALANCE
F8: 18934.67
B11: MOVEMENT LOG — PIX Out
B12: Date | C12: Type | D12: Description | G12: IOF (R$)
B13: 46178 | C13: PIX Out | D13: Eduardo Silva Dos Santos | E13: -480
B14: 46170 | C14: PIX Out | D14: Eduardo Silva Dos Santos | E14: -450
B15: 46167 | C15: PIX Out | D15: Eduardo Silva Dos Santos | E15: -470
B16: 46166 | C16: PIX Out | D16: Moacir Jose De Morais Filho | E16: -700
B17: 46164 | C17: PIX Out | D17: Lucas Rique Chaves Bezerra | E17: -1500
B18: 46164 | C18: PIX Out | D18: Lucas Rique Chaves Bezerra | E18: -500
B19: 46160 | C19: PIX Out | D19: Eduardo Giovannini | E19: -20000
B20: 46140 | C20: PIX Out | D20: Gloria Raquel M C Nobrega | E20: -50
B21: 46140 | C21: PIX Out | D21: Mag Administracao De Negocios Ltda | E21: -10
B22: 46140 | C22: PIX Out | D22: Eduardo Silva Dos Santos | E22: -470
B23: 46136 | C23: PIX Out | D23: 37202818 Jose Periclis De Sousa Da Costa | E23: -6800
B24: 46133 | C24: PIX Out | D24: Eduardo Forster Giovannini | E24: -3000
... B28: 46096 | C28: PIX Out | D28: Mercado Pago Instituicao De Pagamento Ltda | E28: -4582.41

Sheet 08 ALERTS
B1: RISK & ACTION REGISTER · Wealth Management · Q3 2026
B3: # | C3: Severity | D3: Domain | E3: Finding | F3: BRL Exposure | G3: Recommended Action | H3: Status
B4: 1 | C4: CRITICAL | D4: Subscriptions | E4: 4 services flagged CANCEL: Claude x2 (0/mo), Grok (R$149.90/mo), TuneIn (R$31.90/mo). Total savings: R$0/mo · R$0/yr | G4: Cancel all 4 before next billing cycle. Verify via Apple Subscriptions + app accounts | H4: ⏳ Pending
B5: 2 | C5: CRITICAL | D5: Subscription Stack Bloat | E5: R$0/mo in REVIEW = 3 services undecided. Annual exposure R$0 | G5: Audit each REVIEW service this week. Set KEEP/CANCEL decision. Target: eliminate ≥3 | H5: ⏳ Pending
B6: 3 | C6: HIGH | D6: Liquidity Concentration | E6: 100% of liquid assets in 2 digital banks (Inter + MP = R$23,197). BB balance R$0 | F6: 23196.9 | G6: Maintain R$30k+ buffer. Consider distributing across BB (Rende Fácil) and Inter | H6: ⏳ Pending
B7: 4 | C7: HIGH | D7: Lottery/Gambling Spend | E7: R$6,455 in Loteria charges on MP card 2026. No budget cap set | F7: 6455.1 | G7: Set monthly Loteria limit (e.g. R$500). Remove from card if over limit | H7: ⏳ Pending
B8: 5 | C8: MEDIUM | D8: AI/Tech Card Overlap | E8: R$6,624 charged via card on IA/Tech. Likely duplicates subscription stack | F8: 6624.36 | G8: Cross-match card IA charges vs subscription list. Consolidate to single billing method | H8: ⏳ Pending
B9: 6 | C9: MEDIUM | D9: Travel/Viagem Spend | E9: R$9,037 in travel charges. Review vs business vs personal | F9: 9036.83 | G9: Classify each travel expense: business vs personal. Flag deductible items | H9: ⏳ Pending
B10: 7 | C10: MEDIUM | D10: ML Compras Volume | E10: R$31,570 in Mercado Livre purchases (69 items). Strong Home Office + CPAP pattern | F10: 31570.45 | G10: Tag each purchase as CAPEX (equipment), HEALTH, or CONSUMABLE for tax/tracking | H10: ⏳ Pending

Sheet _DATA
A1: Month | B1: Card Spend | D1: Category | E1: Total | J1: Decision | K1: Monthly BRL
A2: 2026-01 | B2: 3745.4 | D2: Viagem | E2: 9036.83 | J2: KEEP | K2: 0
A3: 2026-02 | B3: 9515.9 | D3: Compras/ML | E3: 8744.68 | J3: CANCEL | K3: 0
A4: 2026-03 | B4: 14231.47 | D4: IA/Tecnologia | E4: 6624.36 | J4: REVIEW | K4: 0
A5: 2026-04 | B5: 5330.44 | D5: Loteria | E5: 6455.1
A6: 2026-05 | B6: 3308.38 | D6: Outros | E6: 2235.58
A7: 2026-06 | B7: 1114.17 | D7: Internet | E7: 1413.12
D8: Assinatura | E8: 1227.5
D9: Delivery/iFood | E9: 1217.92

Sheet 09 CHARTS
A1: CHARTS · Wealth Management Visual Analytics · 2026
